<?xml version="1.0" encoding="UTF-8"?>
<testsuite name="Campus Master Data Upload"
           tests="5"
           failures="1"
           errors="0"
           skipped="0"
           time="75.012">
  <properties />
            <testcase name="Edit_Record" time="6.486" classname="Module.HRSetup.Recruitment.TC043_CampusMasterDataUpload">
                <failure type="java.lang.AssertionError"
                  message="expected : [Record Updated Successfully.] but Found : [Record Updated Successfully]"
              >
<![CDATA[java.lang.AssertionError: expected : [Record Updated Successfully.] but Found : [Record Updated Successfully]
  org.testng.Assert.fail(Assert.java:94)
  pom.TestBase.CommonMethods.Test_Edit_Record(CommonMethods.java:172)
  pom.ObjectPages.uiActions.CampusMaster.Test_Edit_Record(CampusMaster.java:135)
  Module.HRSetup.Recruitment.TC043_CampusMasterDataUpload.Edit_Record(TC043_CampusMasterDataUpload.java:107)
  sun.reflect.NativeMethodAccessorImpl.invoke0(Native Method)
  sun.reflect.NativeMethodAccessorImpl.invoke(Unknown Source)
  sun.reflect.DelegatingMethodAccessorImpl.invoke(Unknown Source)
  java.lang.reflect.Method.invoke(Unknown Source)
  org.testng.internal.MethodInvocationHelper.invokeMethod(MethodInvocationHelper.java:85)
  org.testng.internal.Invoker.invokeMethod(Invoker.java:639)
  org.testng.internal.Invoker.invokeTestMethod(Invoker.java:821)
  org.testng.internal.Invoker.invokeTestMethods(Invoker.java:1131)
  org.testng.internal.TestMethodWorker.invokeTestMethods(TestMethodWorker.java:124)
  org.testng.internal.TestMethodWorker.run(TestMethodWorker.java:108)
  org.testng.TestRunner.privateRun(TestRunner.java:773)
  org.testng.TestRunner.run(TestRunner.java:623)
  org.testng.SuiteRunner.runTest(SuiteRunner.java:357)
  org.testng.SuiteRunner.runSequentially(SuiteRunner.java:352)
  org.testng.SuiteRunner.privateRun(SuiteRunner.java:310)
  org.testng.SuiteRunner.run(SuiteRunner.java:259)
  org.testng.SuiteRunnerWorker.runSuite(SuiteRunnerWorker.java:52)
  org.testng.SuiteRunnerWorker.run(SuiteRunnerWorker.java:86)
  org.testng.TestNG.runSuitesSequentially(TestNG.java:1185)
  org.testng.TestNG.runSuitesLocally(TestNG.java:1110)
  org.testng.TestNG.run(TestNG.java:1018)
  org.testng.remote.AbstractRemoteTestNG.run(AbstractRemoteTestNG.java:132)
  org.testng.remote.RemoteTestNG.initAndRun(RemoteTestNG.java:230)
  org.testng.remote.RemoteTestNG.main(RemoteTestNG.java:76)
]]>
      </failure>

          </testcase>
  
  
            <testcase name="Add_New_Button" time="3.107" classname="Module.HRSetup.Recruitment.TC043_CampusMasterDataUpload" />
                <testcase name="TargetPage" time="38.548" classname="Module.HRSetup.Recruitment.TC043_CampusMasterDataUpload" />
                <testcase name="Login" time="1.087" classname="Module.HRSetup.Recruitment.TC043_CampusMasterDataUpload" />
                <testcase name="Add_Allowance_Deduction_Data" time="25.784" classname="Module.HRSetup.Recruitment.TC043_CampusMasterDataUpload" />
      
</testsuite>
