<?xml version="1.0" encoding="UTF-8"?>
<!-- Generated by org.testng.reporters.JUnitReportReporter -->
<testsuite hostname="OSO-DTP-057" name="ESS.LeaveandAttendance.LeaveApplication.TC004_LeaveRevoke" tests="3" failures="0" timestamp="6 Oct 2017 07:37:19 GMT" time="30.774" errors="3">
  <testcase name="TargetPage" time="30.667" classname="ESS.LeaveandAttendance.LeaveApplication.TC004_LeaveRevoke">
    <error type="org.testng.SkipException" message="Not Found Element : Human Resource">
      <![CDATA[org.testng.SkipException: Not Found Element : Human Resource
	at pom.TestBase.BaseClass.click(BaseClass.java:98)
	at pom.TestBase.CommonMethods.TargetPage(CommonMethods.java:26)
	at pom.ObjectPages.uiActions.LeaveApplication.Test_Open_Target_Page(LeaveApplication.java:81)
	at ESS.LeaveandAttendance.LeaveApplication.TC004_LeaveRevoke.TargetPage(TC004_LeaveRevoke.java:62)
	at sun.reflect.NativeMethodAccessorImpl.invoke0(Native Method)
	at sun.reflect.NativeMethodAccessorImpl.invoke(Unknown Source)
	at sun.reflect.DelegatingMethodAccessorImpl.invoke(Unknown Source)
	at java.lang.reflect.Method.invoke(Unknown Source)
	at org.testng.internal.MethodInvocationHelper.invokeMethod(MethodInvocationHelper.java:85)
	at org.testng.internal.Invoker.invokeMethod(Invoker.java:639)
	at org.testng.internal.Invoker.invokeTestMethod(Invoker.java:821)
	at org.testng.internal.Invoker.invokeTestMethods(Invoker.java:1131)
	at org.testng.internal.TestMethodWorker.invokeTestMethods(TestMethodWorker.java:124)
	at org.testng.internal.TestMethodWorker.run(TestMethodWorker.java:108)
	at org.testng.TestRunner.privateRun(TestRunner.java:773)
	at org.testng.TestRunner.run(TestRunner.java:623)
	at org.testng.SuiteRunner.runTest(SuiteRunner.java:357)
	at org.testng.SuiteRunner.access$000(SuiteRunner.java:39)
	at org.testng.SuiteRunner$SuiteWorker.run(SuiteRunner.java:391)
	at org.testng.internal.thread.ThreadUtil$2.call(ThreadUtil.java:64)
	at java.util.concurrent.FutureTask.run(Unknown Source)
	at java.util.concurrent.ThreadPoolExecutor.runWorker(Unknown Source)
	at java.util.concurrent.ThreadPoolExecutor$Worker.run(Unknown Source)
	at java.lang.Thread.run(Unknown Source)
]]>
    </error>
  </testcase> <!-- TargetPage -->
  <testcase name="Login" time="0.107" classname="ESS.LeaveandAttendance.LeaveApplication.TC004_LeaveRevoke">
    <error type="org.testng.SkipException" message="Not Executed this test case">
      <![CDATA[org.testng.SkipException: Not Executed this test case
	at ESS.LeaveandAttendance.LeaveApplication.TC004_LeaveRevoke.Login(TC004_LeaveRevoke.java:52)
	at sun.reflect.NativeMethodAccessorImpl.invoke0(Native Method)
	at sun.reflect.NativeMethodAccessorImpl.invoke(Unknown Source)
	at sun.reflect.DelegatingMethodAccessorImpl.invoke(Unknown Source)
	at java.lang.reflect.Method.invoke(Unknown Source)
	at org.testng.internal.MethodInvocationHelper.invokeMethod(MethodInvocationHelper.java:85)
	at org.testng.internal.Invoker.invokeMethod(Invoker.java:639)
	at org.testng.internal.Invoker.invokeTestMethod(Invoker.java:821)
	at org.testng.internal.Invoker.invokeTestMethods(Invoker.java:1131)
	at org.testng.internal.TestMethodWorker.invokeTestMethods(TestMethodWorker.java:124)
	at org.testng.internal.TestMethodWorker.run(TestMethodWorker.java:108)
	at org.testng.TestRunner.privateRun(TestRunner.java:773)
	at org.testng.TestRunner.run(TestRunner.java:623)
	at org.testng.SuiteRunner.runTest(SuiteRunner.java:357)
	at org.testng.SuiteRunner.access$000(SuiteRunner.java:39)
	at org.testng.SuiteRunner$SuiteWorker.run(SuiteRunner.java:391)
	at org.testng.internal.thread.ThreadUtil$2.call(ThreadUtil.java:64)
	at java.util.concurrent.FutureTask.run(Unknown Source)
	at java.util.concurrent.ThreadPoolExecutor.runWorker(Unknown Source)
	at java.util.concurrent.ThreadPoolExecutor$Worker.run(Unknown Source)
	at java.lang.Thread.run(Unknown Source)
]]>
    </error>
  </testcase> <!-- Login -->
  <testcase name="VerifyLeave" time="0.000" classname="ESS.LeaveandAttendance.LeaveApplication.TC004_LeaveRevoke">
    <error type="java.lang.Throwable" message="Method TC004_LeaveRevoke.VerifyLeave(java.lang.String, java.lang.String, java.lang.String, java.lang.String)[pri:0, instance:ESS.LeaveandAttendance.LeaveApplication.TC004_LeaveRevoke@1df66b6] depends on not successfully finished methods">
      <![CDATA[java.lang.Throwable: Method TC004_LeaveRevoke.VerifyLeave(java.lang.String, java.lang.String, java.lang.String, java.lang.String)[pri:0, instance:ESS.LeaveandAttendance.LeaveApplication.TC004_LeaveRevoke@1df66b6] depends on not successfully finished methods
	at org.testng.internal.Invoker.invokeTestMethods(Invoker.java:1040)
	at org.testng.internal.TestMethodWorker.invokeTestMethods(TestMethodWorker.java:124)
	at org.testng.internal.TestMethodWorker.run(TestMethodWorker.java:108)
	at org.testng.TestRunner.privateRun(TestRunner.java:773)
	at org.testng.TestRunner.run(TestRunner.java:623)
	at org.testng.SuiteRunner.runTest(SuiteRunner.java:357)
	at org.testng.SuiteRunner.access$000(SuiteRunner.java:39)
	at org.testng.SuiteRunner$SuiteWorker.run(SuiteRunner.java:391)
	at org.testng.internal.thread.ThreadUtil$2.call(ThreadUtil.java:64)
	at java.util.concurrent.FutureTask.run(Unknown Source)
	at java.util.concurrent.ThreadPoolExecutor.runWorker(Unknown Source)
	at java.util.concurrent.ThreadPoolExecutor$Worker.run(Unknown Source)
	at java.lang.Thread.run(Unknown Source)
]]>
    </error>
  </testcase> <!-- VerifyLeave -->
</testsuite> <!-- ESS.LeaveandAttendance.LeaveApplication.TC004_LeaveRevoke -->
